root@c29b674f8496:/app# bash /tests/run-tests.sh; tmux wait -S done
Hit:1 http://archive.ubuntu.com/ubuntu noble InRelease
Hit:2 http://archive.ubuntu.com/ubuntu noble-updates InRelease
Hit:3 http://archive.ubuntu.com/ubuntu noble-backports InRelease
Hit:4 http://security.ubuntu.com/ubuntu noble-security InRelease
Reading package lists... Done
Reading package lists... Done
Building dependency tree... Done
Reading state information... Done
curl is already the newest version (8.5.0-2ubuntu10.6).
0 upgraded, 0 newly installed, 0 to remove and 18 not upgraded.
downloading uv 0.7.21 x86_64-unknown-linux-gnu
no checksums to verify
installing to /root/.local/bin
  uv
  uvx
everything's installed!

To add $HOME/.local/bin to your PATH, either restart your shell or run:

    source $HOME/.local/bin/env (sh, bash, zsh)
    source $HOME/.local/bin/env.fish (fish)
Initialized project `app`
Using CPython 3.12.3 interpreter at: /usr/bin/python3.12
Creating virtual environment at: .venv
Resolved 7 packages in 130ms
Prepared 5 packages in 163ms
Installed 5 packages in 26ms
 + iniconfig==2.1.0
 + packaging==25.0
 + pluggy==1.6.0
 + pygments==2.19.2
 + pytest==8.4.1
Resolved 13 packages in 206ms
Prepared 6 packages in 911ms
Installed 6 packages in 92ms
 + numpy==2.3.1
 + pandas==2.2.3
 + python-dateutil==2.9.0.post0
 + pytz==2025.2
 + six==1.17.0
 + tzdata==2025.2
===================================================================== test session starts ======================================================================
platform linux -- Python 3.12.3, pytest-8.4.1, pluggy-1.6.0
rootdir: /tests
collected 2 items

../tests/test_outputs.py .F                                                                                                                              [100%]

=========================================================================== FAILURES ===========================================================================
______________________________________________________________________ test_data_matches _______________________________________________________________________

    def test_data_matches():
        """
        To verify whether the Pandas ETL is correct
        """
        df = pd.read_csv("result.csv", dtype=str)
        df["birth_date"] = pd.to_datetime(
            df["birth_date"],
            format="%Y-%m-%d",
            errors="coerce"
        )

        assert isinstance(df.loc[
            df["participant_id"] == "bd9b6f88-b84f-4c4d-90f8-b67fe2f1a29a",
            "postal_code"
        ].iloc[0], str)
        assert isinstance(df.loc[
            df["participant_id"] == "7dfe3391-6f40-47b6-b4db-0c76ebaf5fc3",
            "postal_code"
        ].iloc[0], str)
        assert isinstance(df.loc[
            df["participant_id"] == "19582d7f-b824-4fe5-a517-d5bf573fc768",
            "postal_code"
        ].iloc[0], str)
        assert isinstance(df.loc[
            df["participant_id"] == "aeb6d817-25f3-4867-8a74-8d92e0a0f633",
            "postal_code"
        ].iloc[0], str)
        assert isinstance(df.loc[
            df["participant_id"] == "1fdabdd9-5444-4c97-87b2-fe8833ad0d27",
            "postal_code"
        ].iloc[0], str)

        assert df.loc[
            df["participant_id"] == "bd9b6f88-b84f-4c4d-90f8-b67fe2f1a29a",
            "postal_code"
        ].iloc[0] == "80734"
        assert df.loc[
            df["participant_id"] == "7dfe3391-6f40-47b6-b4db-0c76ebaf5fc3",
            "postal_code"
        ].iloc[0] == "09434"
        assert df.loc[
            df["participant_id"] == "19582d7f-b824-4fe5-a517-d5bf573fc768",
            "postal_code"
        ].iloc[0] == "57739"
        assert df.loc[
            df["participant_id"] == "aeb6d817-25f3-4867-8a74-8d92e0a0f633",
            "postal_code"
        ].iloc[0] == "76156"
        assert df.loc[
            df["participant_id"] == "1fdabdd9-5444-4c97-87b2-fe8833ad0d27",
            "postal_code"
        ].iloc[0] == "70074"

>       assert df.loc[
            df["participant_id"] == "bd9b6f88-b84f-4c4d-90f8-b67fe2f1a29a",
            "city"
        ].iloc[0] == "Medan"
E       AssertionError: assert 'Medan, Aceh 80734' == 'Medan'
E
E         - Medan
E         + Medan, Aceh 80734

/tests/test_outputs.py:72: AssertionError
============================================================================ PASSES ============================================================================
=================================================================== short test summary info ====================================================================
PASSED ../tests/test_outputs.py::test_result_exists
FAILED ../tests/test_outputs.py::test_data_matches - AssertionError: assert 'Medan, Aceh 80734' == 'Medan'
================================================================= 1 failed, 1 passed in 1.56s ==================================================================
root@c29b674f8496:/app#
